{"uuid": "f0c2f38b-df59-4b41-8282-bc4b4d96843a", "children": ["b7048c45-825b-410e-ad74-171158f2debd"], "befores": [{"name": "login_api", "status": "broken", "statusDetails": {"message": "requests.exceptions.ConnectTimeout: HTTPConnectionPool(host='192.168.6.96', port=80): Max retries exceeded with url: /auth/oauth/token?username=admin&password=7G8EqAsTPjxcn4Mmn7LSpQ%3D%3D&grant_type=password (Caused by ConnectTimeoutError(<urllib3.connection.HTTPConnection object at 0x000001FFC6E88210>, 'Connection to 192.168.6.96 timed out. (connect timeout=None)'))\n", "trace": "  File \"E:\\Lib\\site-packages\\pluggy\\_callers.py\", line 39, in _multicall\n    res = hook_impl.function(*args)\n          ^^^^^^^^^^^^^^^^^^^^^^^^^\n  File \"E:\\Lib\\site-packages\\_pytest\\fixtures.py\", line 1129, in pytest_fixture_setup\n    result = call_fixture_func(fixturefunc, request, kwargs)\n             ^^^^^^^^^^^^^^^^^^^^^^^^^^^^^^^^^^^^^^^^^^^^^^^\n  File \"E:\\Lib\\site-packages\\_pytest\\fixtures.py\", line 901, in call_fixture_func\n    fixture_result = next(generator)\n                     ^^^^^^^^^^^^^^^\n  File \"C:\\Users\\mi\\Documents\\WeChat Files\\wxid_ae2gq2bzzzlp22\\FileStorage\\TempFromPhone\\api\\api\\api_framework\\TestCases\\conftest.py\", line 16, in login_api\n  File \"E:\\Lib\\site-packages\\requests\\sessions.py\", line 587, in request\n    resp = self.send(prep, **send_kwargs)\n           ^^^^^^^^^^^^^^^^^^^^^^^^^^^^^^\n  File \"E:\\Lib\\site-packages\\requests\\sessions.py\", line 701, in send\n    r = adapter.send(request, **kwargs)\n        ^^^^^^^^^^^^^^^^^^^^^^^^^^^^^^^\n  File \"E:\\Lib\\site-packages\\requests\\adapters.py\", line 553, in send\n    raise ConnectTimeout(e, request=request)\n"}, "start": 1676623466741, "stop": 1676623487746}], "start": 1676623466741, "stop": 1676623487824}