{"uuid": "4d4d8a67-2efc-40b4-9d70-ba54ad868ec9", "children": ["2834b919-156d-4f6c-a6f2-b9628927c3ce", "39915a49-a125-4cb4-af6e-bd7bd8552f71"], "befores": [{"name": "login_api", "status": "broken", "statusDetails": {"message": "requests.exceptions.ConnectTimeout: HTTPConnectionPool(host='192.168.6.96', port=80): Max retries exceeded with url: /auth/oauth/token?username=admin&password=7G8EqAsTPjxcn4Mmn7LSpQ%3D%3D&grant_type=password (Caused by ConnectTimeoutError(<urllib3.connection.HTTPConnection object at 0x000001FFC70C7CD0>, 'Connection to 192.168.6.96 timed out. (connect timeout=None)'))\n", "trace": "  File \"E:\\Lib\\site-packages\\pluggy\\_callers.py\", line 39, in _multicall\n    res = hook_impl.function(*args)\n          ^^^^^^^^^^^^^^^^^^^^^^^^^\n  File \"E:\\Lib\\site-packages\\_pytest\\fixtures.py\", line 1129, in pytest_fixture_setup\n    result = call_fixture_func(fixturefunc, request, kwargs)\n             ^^^^^^^^^^^^^^^^^^^^^^^^^^^^^^^^^^^^^^^^^^^^^^^\n  File \"E:\\Lib\\site-packages\\_pytest\\fixtures.py\", line 901, in call_fixture_func\n    fixture_result = next(generator)\n                     ^^^^^^^^^^^^^^^\n  File \"C:\\Users\\mi\\Documents\\WeChat Files\\wxid_ae2gq2bzzzlp22\\FileStorage\\TempFromPhone\\api\\api\\api_framework\\TestCases\\conftest.py\", line 16, in login_api\n  File \"E:\\Lib\\site-packages\\requests\\sessions.py\", line 587, in request\n    resp = self.send(prep, **send_kwargs)\n           ^^^^^^^^^^^^^^^^^^^^^^^^^^^^^^\n  File \"E:\\Lib\\site-packages\\requests\\sessions.py\", line 701, in send\n    r = adapter.send(request, **kwargs)\n        ^^^^^^^^^^^^^^^^^^^^^^^^^^^^^^^\n  File \"E:\\Lib\\site-packages\\requests\\adapters.py\", line 553, in send\n    raise ConnectTimeout(e, request=request)\n"}, "start": 1676623530114, "stop": 1676623551118}], "start": 1676623530114, "stop": 1676623551315}